Workbook

Sheet 00_Huong dan
A1: Hệ thống hỗ trợ nghiệp vụ Food Cold-Chain (YCCMS) — Gói đề xuất (BẢN CHUẨN RFP YCL-RFP-2026-01 (v2.0, 2026-08-13))
A2: Khách: ユキコールドロジスティクス株式会社 | Vendor: Sun* (Sun Asterisk) — Sun VN02 | PL: Thanh Ta | 2026-10-02 | v2.0 (rebuild bám RFP) | Go-live 2027-06-01
A4: # | B4: Sheet | C4: Nội dung
A5: 1 | B5: 01_Cau hoi khach | C5: Câu hỏi gửi khách (đã lọc theo RFP)
A6: 2 | B6: 02_Function list | C6: 12 nhóm chức năng (map domain RFP)
A7: 3 | B7: 03_Feature list | C7: 47 feature, mỗi feature gắn mã FR/BR/NFR
A8: 4 | B8: 04_Man hinh | C8: 41 màn hình
A9: 5 | B9: 05_User stories | C9: 12 user story theo fixture R-06
A10: 6 | B10: 06_Compliance (88) | C10: MA TRẬN TUÂN THỦ yêu cầu (Comply/Partial/Assumption)
A11: 7 | B11: 07_Estimate-WBS | C11: Estimate effort + WBS (có công thức)
A12: 8 | B12: 08_Cost (S5-02) | C12: Cost theo template S5-02 (one-time/định kỳ/option)
A13: 9 | B13: 09_Rui ro | C13: Rủi ro + bẫy đọc-hiểu (重大エラー S5-03)
A14: 10 | B14: 10_Du lieu RFP | C14: 12 SKU + sự thật nền + quy tắc lõi
B16: QUY TẮC LÕI (chính xác theo RFP)
A17: ◆ | B17: FEFO (先期限先出し) | C17: Chọn lô HSD sớm nhất; CÙNG HSD mới dùng FIFO (先入れ先出し) làm tie-break. Lô 隔離 không đủ điều kiện.
A18: ◆ | B18: Chuỗi loại trừ allocation (FR-OUT-02) | C18: Thứ tự cố định: ① 消費期限 quá hạn (hard stop) → ② lệch dải nhiệt (BR-TEMP-02) → ③ đang 隔離 (FR-INV-05) → ④ vi phạm delivery window (BR-DELWIN-01) → ⑤ 日付逆転 (BR-DATE-01) → ⑥ còn lại theo FEFO, cùng HSD thì FIFO. D3 định nghĩa rule, D4 chỉ thực thi thứ tự.
A19: ◆ | B19: 2 loại hạn | C19: 賞味期限 = cảnh báo (chất lượng); 消費期限 = HARD STOP khi đạt/quá (an toàn). Khai theo SKU (BR-EXP-01/02).
A20: ◆ | B20: 日付逆転禁止 (BR-DATE-01) | C20: So HSD lô định giao với lần giao gần nhất của ĐÚNG cặp khách-SKU; KHÔNG so hôm nay; không mượn lịch sử khách khác. (VD: CUS-003/CHI-002)
A21: ◆ | B21: Quy tắc 1/3 – 1/2 (BR-DELWIN-01) | C21: 納品期限 theo hợp đồng (ONE_THIRD/ONE_HALF/LABEL_DATE_ONLY) — TẬP QUÁN thương mại, KHÔNG phải luật; không mặc định cho dòng chưa chốt.
A22: ◆ | B22: Giới hạn giờ lái (FR-SCH-02, số Yuki) | C22: 960h超勤/năm · 3.300h拘束/năm · 284h/tháng · 13h/ngày (tối đa 15h) · nghỉ 11h mục tiêu/9h tối thiểu · lái TB 9h/ngày (2 ngày), 44h/tuần (2 tuần) · lái liên tục ≤ 4h. Vi phạm → cấm publish.
A23: ◆ | B23: Truy xuất 3 lane (BR-TRACE) | C23: gạo (産地+取引, pháp định) · bò (mã cá thể 10 số, pháp định) · nội bộ (lô + link NCC/khách, không bắt buộc). Bò 9 số → business-review, không tự làm tròn.
A24: ◆ | B24: Bất biến & maker-checker | C24: Event bất biến (sửa = reversal/new version, cấm overwrite); người lập ≠ người duyệt (NFR-SEC-02); 隔離 khóa tồn thật; blind count + duyệt 2 cấp.
A25: ◆ | B25: POD theo điều kiện (BR-POD-01) | C25: 車上渡し vs 軒先渡し khác checkpoint/evidence; ảnh hash, không nhúng ảnh vào CSV; queue offline mã hóa ≤ 8h; kho không offline.

Sheet 01_Cau hoi khach
A1: Deliverable 1 — Câu hỏi gửi khách
A2: Đã bỏ các câu RFP đã trả lời (SKU, dải nhiệt, user, FEFO, go-live, SSO). Chỉ còn điểm thật sự mở.
A4: ID | B4: Chủ đề | C4: Câu hỏi | D4: Loại | E4: Giả định hiện tại | F4: Ảnh hưởng estimate
A5: Q-01 | B5: Interface ERP | C5: Đặc tả schema CSV/SFTP của ERP (trường, khóa, lịch batch, idempotency key) như thế nào? | D5: Chặn báo giá | E5: Giả định: 1 schema CSV chuẩn, batch ngày. | F5: Nhiều schema/đối tác → +MD adapter & test.
A6: Q-02 | B6: Mapping service | C6: License mapping service (distance/travel time) do Yuki cấp hay Sun* mua? Hạn mức/giá? | D6: Chặn báo giá | E6: Giả định: Yuki cấp license (IF-MAP-01). | F6: Sun* mua → thêm chi phí định kỳ + tích hợp.
A7: Q-03 | B7: IdP / SSO | C7: IdP doanh nghiệp (OIDC) là gì, cơ chế managed device cho tài xế? | D7: Chặn báo giá | E7: Giả định: có IdP OIDC + MDM cho tài xế. | F7: Chưa có → +thiết lập & +MD.
A8: Q-04 | B8: Datalogger CSV | C8: Định dạng CSV logger chính xác, cơ chế hash & timezone của thiết bị? | D8: Chặn báo giá | E8: Giả định: 1 định dạng + hash + timezone rõ. | F8: Nhiều định dạng → +adapter.
A9: Q-05 | B9: Hạ tầng | C9: Cloud vùng Nhật được duyệt? Ràng buộc lưu trú dữ liệu, SLA hosting? | D9: Chặn báo giá | E9: Giả định: cloud vùng Nhật, 99.5% (NFR-AVL-01). | F9: On-prem → +chi phí/tiến độ.
A10: Q-06 | B10: Tiền tệ & thanh toán | C10: Tiền tệ báo giá, xử lý thuế, mốc thanh toán gắn ACC-GO-01? | D10: Chặn báo giá | E10: Giả định: JPY, thanh toán theo milestone nghiệm thu. | F10: Ảnh hưởng cost sheet & hợp đồng.
A11: Q-07 | B11: Option Phase 2 | C11: Yuki có muốn báo giá kèm option nào (online logger, dự báo, GPS…) ngay không? | D11: Hỏi sau | E11: Giả định: chỉ base; option liệt kê giá tham khảo. | F11: Thêm option → +scope.
A12: Q-08 | B12: AGR chưa chốt | C12: Khi nào chốt rule cho AGR-008 & AGR-014? Quy trình cập nhật? | D12: Hỏi sau | E12: Giả định: giữ business-review tới khi khách chốt. | F12: Không ảnh hưởng kiến trúc.
A13: Q-09 | B13: Onsite | C13: Mức độ cần onsite tại Nhật (cutover/UAT/training)? | D13: Hỏi sau | E13: Giả định: onsite giai đoạn cutover & UAT. | F13: Ảnh hưởng chi phí công tác.
A14: Q-10 | B14: Báo cáo & KPI | C14: Chi tiết 12 báo cáo & định nghĩa KPI (phân tử/mẫu/except) có sẵn chưa? | D14: Hỏi sau | E14: Giả định: theo catalog D8; chốt chi tiết ở BD. | F14: Tùy biến nhiều → +MD.

Sheet 02_Function list
A1: Deliverable 2 — Function list (12 nhóm)
A2: Map theo domain RFP D1–D8 + S3/S4.
A4: ID | B4: Nhóm chức năng | C4: Phạm vi / mã liên quan
A5: F01 | B5: Master & dữ liệu nền | C5: SKU/customer-SKU contract/supplier/location/device; effective-dated; maker-checker (DR-MST-01).
A6: F02 | B6: Nhập & kiểm hàng | C6: Appointment, kiểm nhập (nhiệt/lô/hạn/ảnh), tạo lô bất biến, 隔離 (FR-REC-*).
A7: F03 | B7: Tồn kho, lô & 3 dải nhiệt | C7: Vị trí/sức chứa, put-away, FEFO access, blind count, state machine 隔離 (FR-INV-*, BR-TEMP).
A8: F04 | B8: Hạn dùng, FEFO & delivery window | C8: 2 loại hạn, FEFO/FIFO, 日付逆転, window 1/3-1/2 (BR-EXP/FEFO/DATE/DELWIN).
A9: F05 | B9: Xuất kho, allocation & POD | C9: Đơn, allocation theo chuỗi loại trừ, pick/load kiểm soát, POD 車上/軒先 (FR-OUT-*, BR-POD).
A10: F06 | B10: Lập tuyến & giờ lái | C10: Tuyến, kiểm ràng buộc giờ lái, version publish, sự cố (FR-SCH-*).
A11: F07 | B11: Giám sát nhiệt & HACCP | C11: Import CSV logger, đánh giá reading, alarm/deviation, completeness HACCP (FR-TEMP-*, BR-HACCP).
A12: F08 | B12: Truy xuất & recall | C12: 3 lane (gạo/bò/nội bộ), truy vết xuôi-ngược, recall + đối soát số lượng (FR-TRC-*, BR-TRACE).
A13: F09 | B13: Báo cáo, KPI & audit | C13: 12 báo cáo, audit export manifest, KPI theo đo lường chuẩn (FR-RPT-*, NFR-AUD-01).
A14: F10 | B14: Tích hợp & trao đổi file | C14: ERP SFTP, logger CSV, mapping service, OIDC, mail relay, archive (IF-*).
A15: F11 | B15: Bảo mật, phân quyền & chất lượng NFR | C15: SSO/MFA/RBAC/mã hóa, performance/BCP/observability/WCAG (NFR-*, ACC-NFR-01).
A16: F12 | B16: Migration & chuyển đổi | C16: Lineage, 2 rehearsal, đối soát, cutover/parallel, training (DR-MIG-01, S4).

Sheet 03_Feature list
A1: Deliverable 3 — Feature list (47)
A2: Mỗi feature gắn đúng 1 function + mã yêu cầu RFP (FR/BR/NFR/DR/IF).
A4: ID | B4: Func | C4: Tính năng | D4: Mã yêu cầu | E4: Ưu tiên
A5: FE-01 | B5: F01 | C5: Quản lý SKU (dải nhiệt, loại hạn, lane truy xuất, regulated id) | D5: DR-MST-01, BR-EXP-01 | E5: P0
A6: FE-02 | B6: F01 | C6: Hợp đồng khách-SKU (delivery_term, delivery_window_rule, effective) | D6: DR-MST-01, BR-DELWIN-01 | E6: P0
A7: FE-03 | B7: F01 | C7: Master NCC / vị trí (zone) / device + vòng đời created→active→retired | D7: DR-MST-01 | E7: P0
A8: FE-04 | B8: F01 | C8: Maker-checker: người lập không tự duyệt bản ghi | D8: NFR-SEC-02 | E8: P0
A9: FE-05 | B9: F02 | C9: Appointment nhập + cảnh báo trùng tham chiếu NCC | D9: FR-REC-01 | E9: P1
A10: FE-06 | B10: F02 | C10: Kiểm nhập (field P0 bắt buộc) + tạo lô/stock unit bất biến idempotent | D10: FR-REC-02, FR-REC-04 | E10: P0
A11: FE-07 | B11: F02 | C11: Nhận/từ chối/giữ + mã lý do; chuyển 隔離 khi lỗi | D11: FR-REC-03, FR-REC-05 | E11: P0
A12: FE-08 | B12: F03 | C12: Vị trí: sức chứa/dải nhiệt/tình trạng; gợi ý vị trí hợp lệ | D12: FR-INV-01, FR-INV-02 | E12: P1
A13: FE-09 | B13: F03 | C13: Ghi mọi di chuyển; cấm tồn âm/ngoài dải nhiệt; idempotent | D13: FR-INV-03 | E13: P0
A14: FE-10 | B14: F03 | C14: State machine 隔離 (available→quarantine→release/scrap) + khóa tồn | D14: FR-INV-05 | E14: P0
A15: FE-11 | B15: F03 | C15: Blind count + duyệt 2 cấp khi chênh lệch vượt ngưỡng | D15: FR-INV-04 | E15: P1
... A51: FE-47 | B51: F12 | C51: Cutover + parallel-run (old = read-only) + rollback | D51: ACC-GO-01 | E51: P0

Sheet 04_Man hinh
A1: Deliverable 4 — Danh sách màn hình (41)
A2: Đầu vào LAB-2/3. Cột 'Độ PT' (S/M/C) dùng cho estimate (sheet 07).
A4: SCR | B4: Tên màn hình | C4: Func | D4: Actor | E4: Loại | F4: Độ PT | G4: Ưu tiên
A5: SCR-00 | B5: Đăng nhập (SSO/OIDC) | C5: F11 | D5: Tất cả | E5: Form | F5: S | G5: P0
A6: SCR-01 | B6: Dashboard vận hành & KPI | C6: F09 | D6: Quản lý | E6: Dashboard | F6: C | G6: P1
A7: SCR-02 | B7: Master SKU (hạn/lane/dải nhiệt) | C7: F01 | D7: Admin/QA | E7: Form | F7: M | G7: P0
A8: SCR-03 | B8: Hợp đồng khách-SKU (window/term) | C8: F01 | D8: Sales/Admin | E8: Form | F8: M | G8: P0
A9: SCR-04 | B9: Master NCC/vị trí/device | C9: F01 | D9: Admin | E9: List+Form | F9: M | G9: P0
A10: SCR-05 | B10: Hàng chờ duyệt (maker-checker) | C10: F01 | D10: Approver | E10: List | F10: M | G10: P0
A11: SCR-06 | B11: Appointment nhập | C11: F02 | D11: Kho | E11: List+Form | F11: M | G11: P1
A12: SCR-07 | B12: Kiểm nhập (nhiệt/lô/hạn/ảnh) | C12: F02 | D12: Kho | E12: Form | F12: C | G12: P0
A13: SCR-08 | B13: Tồn kho đa tiêu chí | C13: F03 | D13: Kho/QL | E13: List | F13: M | G13: P1
A14: SCR-09 | B14: Vị trí & put-away gợi ý | C14: F03 | D14: Kho | E14: Form | F14: M | G14: P1
A15: SCR-10 | B15: 隔離 / release / scrap | C15: F03 | D15: QA | E15: Form | F15: C | G15: P0
... A45: SCR-40 | B45: Cấu hình hệ thống & tham số | C45: F11 | D45: Admin | E45: Form | F45: M | G45: P1

Sheet 05_User stories
A1: Deliverable 5 — User stories (fixture R-06)
A2: Acceptance criteria dùng đúng dữ liệu RFP (CUS-003/CHI-002, bò 9 số, AGR-008/014…).
A4: ID | B4: Là (actor) | C4: Tôi muốn | D4: Để mà | E4: Acceptance criteria | F4: Mã yêu cầu | G4: Ưu tiên
A5: US-01 | B5: Nhân viên kho | C5: được allocation theo đúng chuỗi loại trừ 6 bước | D5: không giao lô vi phạm bất kỳ quy tắc nào | E5: • Thứ tự: 消費期限 quá hạn → lệch dải nhiệt → 隔離 → delivery window → 日付逆転 → FEFO (cùng HSD→FIFO) • Allocation nguyên tử: 2 request song song không over-allocate cùng lô • Mỗi lần loại trừ ghi rõ lý do + dữ liệu dùng | F5: FR-OUT-02, BR-EXP-02, BR-FEFO-01, BR-DATE-01 | G5: P0
A6: US-02 | B6: Nhân viên giao vận | C6: bị CHẶN khi lô có HSD cũ hơn lần giao gần nhất của đúng cặp khách-SKU | D6: không vi phạm 日付逆転禁止 | E6: • Given CUS-003/CHI-002 đã nhận HSD 2026-09-20; When allocation đề xuất HSD 2026-09-18; Then CHẶN dù hôm nay còn xa HSD • CUS-004 cùng SKU nhưng không có lịch sử → KHÔNG dùng lịch sử CUS-003 • Lịch sử giao bất biến (DR-HIST-01); ngoại lệ chỉ quản lý duyệt + audit | F6: BR-DATE-01, DR-HIST-01 | G6: P0
A7: US-03 | B7: Nhân viên QA | C7: có 消費期限 là HARD STOP còn 賞味期限 là cảnh báo | D7: chặn đúng hàng mất an toàn, cảnh báo đúng hàng giảm chất lượng | E7: • 消費期限 đạt/quá → chặn allocation & giao + exception bất biến (BR-EXP-02) • 賞味期限 quá window → cảnh báo (không hard block), nêu rõ 'tập quán, không phải hạn thực' • Mỗi SKU chỉ 1 loại hạn; đổi loại hạn ghi audit | F7: BR-EXP-01, BR-EXP-02, BR-DELWIN-01 | G7: P0
A8: US-04 | B8: Sales/Admin | C8: cấu hình delivery window theo hợp đồng khách-SKU | D8: áp đúng tập quán từng dòng, không đoán dòng chưa chốt | E8: • ONE_THIRD / ONE_HALF / LABEL_DATE_ONLY theo agreement • AGR-008/AGR-014 chưa chốt → giữ trạng thái business-review, KHÔNG mặc định • Thêm rule sau không đổi cấu trúc dữ liệu | F8: BR-DELWIN-01 | G8: P0
A9: US-05 | B9: Nhân viên kho | C9: được gợi ý lô theo FEFO và loại lô 隔離 | D9: xuất đúng thứ tự hạn và không chạm hàng đang cách ly | E9: • Chọn HSD sớm nhất; cùng HSD theo giờ nhập (FIFO) • Lô 隔離 không xuất hiện kể cả khi HSD sớm hơn • Chọn khác gợi ý phải có lý do + ghi vết | F9: BR-FEFO-01, FR-INV-05 | G9: P0
A10: US-06 | B10: Nhân viên 配車計画 | C10: được kiểm ràng buộc giờ lái trước khi publish tuyến | D10: lịch không vi phạm quy định | E10: • Kiểm 超勤 960h/năm, 拘束 3.300h/năm & 284h/tháng, ngày ≤13h (tối đa 15h), nghỉ ≥9h, lái liên tục ≤4h • Vi phạm → CẤM publish + nêu chính xác khoảng giờ vi phạm • Tuyến publish gắn version bản quy tắc; đổi sau publish cần lý do | F10: FR-SCH-02, FR-SCH-04 | G10: P0
A11: US-07 | B11: QA | C11: import CSV logger có hash và được cảnh báo khi vượt ngưỡng | D11: giám sát chuỗi lạnh phục vụ HACCP | E11: • Cùng hash → xử lý idempotent; dòng sai format bị từ chối kèm số dòng • Đánh giá theo threshold version của SKU/zone; lưu first/last/peak/duration + lô ảnh hưởng • Alarm chưa xử lý hiển thị thời gian còn lại trước SLA 15′ | F11: FR-TEMP-01, FR-TEMP-02, FR-TEMP-03 | G11: P0
A12: US-08 | B12: QA | C12: truy xuất 3 lane đúng bản chất | D12: đáp ứng pháp định gạo/bò và truy nội bộ | E12: • Gạo: 産地+取引; Bò: mã cá thể 10 số xuyên suốt; thiếu/không đúng 10 số → chặn • Bò 9 số (fixture dòng 210) → business-review, KHÔNG tự làm tròn thành 10 • Recall: affected = on-hand + shipped = returned + unresolved + disposed | F12: BR-TRACE-01, BR-TRACE-02, FR-TRC-02 | G12: P0
A13: US-09 | B13: Tài xế | C13: ghi POD theo đúng điều kiện giao | D13: bằng chứng khớp hợp đồng, giảm tranh chấp | E13: • 車上渡し và 軒先渡し có checkpoint/evidence khác nhau (BR-POD-01) • Ảnh hash khi upload; không nhúng ảnh vào CSV; sửa = version mới link bản cũ • Mất mạng: queue mã hóa ≤8h, đối soát 1 lần khi online | F13: FR-OUT-06, BR-POD-01, NFR-AVL-02 | G13: P0
A14: US-10 | B14: Data lead | C14: chạy migration có lineage và xử lý dirty data | D14: không suy diễn dữ liệu mập mờ, có đối soát | E14: • Mỗi dòng: ACCEPT/REJECT/DUPLICATE/BUSINESS-REVIEW + lý do + source row • HSD trống / nhiều định dạng ngày / Excel serial / đổi mã khách / dòng hoàn âm: không tự sửa • Mỗi rehearsal: source = accept + reject + duplicate; business owner ký exception | F14: DR-MIG-01, ACC-MIG-01 | G14: P0
A15: US-11 | B15: Admin | C15: đăng nhập SSO, quyền cao có MFA, phân quyền RBAC + maker-checker | D15: bảo mật và tách trách nhiệm | E15: • SSO/OIDC; MFA cho role đặc quyền; tài xế dùng managed device • Người lập bản ghi không tự duyệt bản ghi đó • Mọi state/master/approval/export/auth ghi append-only | F15: NFR-SEC-01, NFR-SEC-02, NFR-AUD-01 | G15: P0
A16: US-12 | B16: Auditor | C16: xuất bằng chứng audit tái tạo được | D16: trả lời câu hỏi kiểm toán nhanh | E16: • Export có checksum manifest; người có quyền tái tạo đúng kết quả • Chỉ đọc; quyền xem/sensitive/retention kế thừa từ dữ liệu nguồn | F16: FR-RPT-02, NFR-AUD-01 | G16: P0

Sheet 06_Compliance (88)
A1: Deliverable 6 — Ma trận tuân thủ yêu cầu (RFP nêu 88; bảng liệt kê 89 mã gồm 2 ràng buộc NUM)
A2: Comply / Partial / Assumption theo S5-01 §2. Mỗi dòng Assumption nêu phụ thuộc cần làm rõ.
A4: Mã | B4: Nhóm | C4: Yêu cầu | D4: Ưu tiên | E4: Tuân thủ | F4: Ghi chú
A5: FR-REC-01 | B5: D1 Nhập | C5: Tạo appointment nhập: ETA NCC, dải nhiệt xe, số dòng dự kiến; cảnh báo trùng mã tham chiếu NCC | D5: P1 | E5: Comply
A6: FR-REC-02 | B6: D1 Nhập | C6: Ghi kiểm từng dòng: đóng gói, SL, lô, loại hạn, HSD, nhiệt đo, ảnh; thiếu field P0 → chặn | D6: P0 | E6: Comply | F6: Chốt kiểm nhập
A7: FR-REC-03 | B7: D1 Nhập | C7: Ghi nhận/từ chối/giữ SL + mã lý do; tổng khớp số báo hoặc duyệt phân tán | D7: P1 | E7: Comply
A8: FR-REC-04 | B8: D1 Nhập | C8: Tạo lô & stock unit bất biến; idempotent khi retry (không trùng khóa lô) | D8: P0 | E8: Comply | F8: Bất biến + idempotent
A9: FR-REC-05 | B9: D1 Nhập | C9: Chuyển 隔離 khi lỗi nhiệt/truy xuất; hàng 隔離 không giữ chỗ/pick | D9: P0 | E9: Comply
A10: FR-INV-01 | B10: D2 Tồn kho | C10: Giữ sức chứa/dải nhiệt/tình trạng theo vị trí; put-away vượt chứa/vị trí đóng → chặn | D10: P1 | E10: Comply
A11: FR-INV-02 | B11: D2 Tồn kho | C11: Gợi ý vị trí hợp lệ theo dải nhiệt/tình trạng/khả năng FEFO; vị trí sai luôn bị chặn | D11: P1 | E11: Comply
A12: FR-INV-03 | B12: D2 Tồn kho | C12: Ghi mọi di chuyển (nguồn/đích/lô/SL/actor/device/giờ); cấm tồn âm & chuyển ngoài dải nhiệt | D12: P0 | E12: Comply
A13: FR-INV-04 | B13: D2 Tồn kho | C13: Blind count (ẩn số tồn); chênh lệch cần lý do + duyệt 2 cấp (maker-checker) | D13: P1 | E13: Comply | F13: Maker-checker
A14: FR-INV-05 | B14: D2 Tồn kho | C14: State machine available/quarantine/release/scrap, chỉ chuyển hợp lệ, lịch sử bất biến | D14: P0 | E14: Comply | F14: 隔離 khóa tồn
A15: FR-INV-06 | B15: D2 Tồn kho | C15: Tìm tồn đa tiêu chí (SKU/lô/NCC/HSD/loại hạn/dải nhiệt/tình trạng/vị trí) | D15: P1 | E15: Comply
A16: FR-OUT-01 | B16: D4 Xuất | C16: Tạo dòng đơn (khách/SKU/SL/ngày/điều kiện giao/tham chiếu); lỗi master & trùng xử lý được | D16: P0 | E16: Comply
A17: FR-OUT-02 | B17: D4 Xuất | C17: Allocation nguyên tử theo chuỗi loại trừ (消費→nhiệt→隔離→window→日付逆転→FEFO/FIFO); không over-allocate | D17: P0 | E17: Comply | F17: LÕI nghiệp vụ
A18: FR-OUT-03 | B18: D4 Xuất | C18: Gom pick theo khu/tuyến/thứ tự tải; đổi task giữ allocation gốc + audit | D18: P1 | E18: Comply
A19: FR-OUT-04 | B19: D4 Xuất | C19: Kiểm pick/tải bằng barcode/nhập kiểm soát (SKU/lô/SL/xe/seal); lỗi → chặn tải | D19: P0 | E19: Comply
A20: FR-OUT-05 | B20: D4 Xuất | C20: Ghi kiểm trước xuất (nhiệt xe/nhiệt hàng/seal/giờ); ngoài policy → deviation + chặn | D20: P0 | E20: Comply
A21: FR-OUT-06 | B21: D4 Xuất | C21: POD theo điều kiện (giờ/vị trí/người nhận/chữ ký-ảnh/mã ngoại lệ); queue offline mã hóa, đối soát 1 lần | D21: P0 | E21: Comply | F21: Offline ≤8h
A22: FR-OUT-07 | B22: D4 Xuất | C22: Liên kết trả hàng/khiếu nại với dòng giao/lô/bằng chứng/tình trạng/chuỗi giám hộ | D22: P1 | E22: Comply
A23: FR-SCH-01 | B23: D5 Lập tuyến | C23: Lập tuyến từ đơn/dải nhiệt xe/khung giờ/service time/giờ depot; đơn chưa gán + lý do hiển thị | D23: P0 | E23: Comply
A24: FR-SCH-02 | B24: D5 Lập tuyến | C24: Kiểm 超勤/tổng giờ/nghỉ/lái TB/lái liên tục theo bản quy tắc; vi phạm → cấm publish + nêu khoảng giờ | D24: P0 | E24: Comply | F24: Số giờ chính xác
A25: FR-SCH-03 | B25: D5 Lập tuyến | C25: Chèn nghỉ đủ trước khi lái liên tục quá 4h; vị trí/thời lượng nghỉ hiển thị | D25: P1 | E25: Comply
A26: FR-SCH-04 | B26: D5 Lập tuyến | C26: Publish tuyến có version; đổi sau publish cần lý do; tài xế nhận bản mới nhất, bản cũ audit | D26: P0 | E26: Comply
A27: FR-SCH-05 | B27: D5 Lập tuyến | C27: Ghi sự cố (tai nạn/hỏng xe/thiên tai) riêng, bất biến, không ghi đè tuân thủ | D27: P1 | E27: Comply
A28: FR-TEMP-01 | B28: D6 Nhiệt/HACCP | C28: Import CSV logger có hash+device timestamp+timezone; cùng hash idempotent; dòng lỗi từ chối kèm số dòng | D28: P0 | E28: Comply
A29: FR-TEMP-02 | B29: D6 Nhiệt/HACCP | C29: Đánh giá reading theo policy/threshold SKU/zone; lưu first/last/peak/duration+version+lô ảnh hưởng | D29: P0 | E29: Comply
A30: FR-TEMP-03 | B30: D6 Nhiệt/HACCP | C30: Hiển thị alarm chưa xử lý; ghi review đầu trong 15′; review trễ đánh dấu & vào báo cáo | D30: P0 | E30: Comply
A31: FR-TEMP-04 | B31: D6 Nhiệt/HACCP | C31: Deviation case (alarm→investigation→evidence→inventory→corrective→decision); thiếu rationale/đính kèm → không đóng | D31: P0 | E31: Comply
A32: FR-TRC-01 | B32: D7 Truy xuất | C32: Truy xuất từ lô/SKU/NCC/産地 gạo/mã bò → tồn & giao liên quan; chỉ rõ điểm đứt liên kết | D32: P0 | E32: Comply
A33: FR-TRC-02 | B33: D7 Truy xuất | C33: Recall case (scope/lô/khách/SL/liên hệ/task/hạn); đối soát affected=on-hand+shipped=returned+unresolved+disposed | D33: P0 | E33: Comply
A34: FR-TRC-03 | B34: D7 Truy xuất | C34: Sinh thông báo recall (khách/nội bộ) có version, cần approver trước gửi | D34: P1 | E34: Comply
A35: FR-RPT-01 | B35: D8 Báo cáo | C35: 12 báo cáo vận hành (lọc kỳ/khách/SKU/dải/tình trạng + xuất CSV + quyền theo role) | D35: P1 | E35: Comply
A36: FR-RPT-02 | B36: D8 Báo cáo | C36: Xuất bằng chứng audit (case/event/đính kèm/index/source hash) + checksum manifest tái tạo được | D36: P0 | E36: Comply
... A48: BR-TRACE-03 | B48: Rule truy xuất | C48: Lane nội bộ giữ lô nội bộ + link NCC/khách dạng dữ liệu cấu trúc (không free-text) | D48: P1 | E48: Comply
A49: NFR-PERF-01 | B49: NFR Hiệu năng | C49: p95 read ≤2s / write ≤3s @ 80 concurrent; load test đúng 80 user | D49: P0 | E49: Comply | F49: Cần hạ tầng + load test
A50: NFR-PERF-02 | B50: NFR Hiệu năng | C50: Trace 3 năm ≤60s; dataset 300.000 shipment lines + 2,5M temp readings | D50: P0 | E50: Comply
A51: NFR-BCP-01 | B51: NFR Liên tục | C51: RTO 4h, RPO 15′; restore drill hàng quý | D51: P0 | E51: Comply
A52: NFR-AVL-01 | B52: NFR Liên tục | C52: 99.5%/tháng trong 05:00–23:00 JST (trừ bảo trì đã duyệt) | D52: P0 | E52: Comply
...

Sheet 07_Estimate-WBS
A1: Deliverable 7 — Estimate effort + WBS (MD = man-day)
A2: Build suy từ sheet 04 (S/M/C). Ô vàng = giả định chỉnh được. Gồm workstream NFR & migration theo RFP.
A4: A. Đơn giá màn hình (MD) + đếm từ sheet 04
A5: Độ PT | B5: Mô tả | C5: Đơn giá | D5: Số MH | E5: Thành (MD)
A6: S | B6: Đơn giản | C6: 2.5 | D6: =COUNTIF('04_Man hinh'!$F:$F,"S") -> 2 | E6: =C6*D6 -> 5
A7: M | B7: Trung bình | C7: 4.5 | D7: =COUNTIF('04_Man hinh'!$F:$F,"M") -> 25 | E7: =C7*D7 -> 112.5
A8: C | B8: Phức tạp | C8: 9 | D8: =COUNTIF('04_Man hinh'!$F:$F,"C") -> 14 | E8: =C8*D8 -> 126
B9: Cộng build màn hình | E9: =SUM(E6:E8) -> 243.5
A11: B. Engine / xử lý lõi
A12: ID | B12: Hạng mục | C12: Func | E12: MD
A13: ENG-01 | B13: Allocation engine (chuỗi loại trừ 6 bước, nguyên tử, idempotent) | C13: F05 | E13: 22
A14: ENG-02 | B14: FEFO + 日付逆転 (lịch sử bất biến theo khách-SKU) | C14: F04 | E14: 12
A15: ENG-03 | B15: Hạn dùng (2 loại) + delivery window 1/3-1/2 theo hợp đồng | C15: F04 | E15: 8
A16: ENG-04 | B16: Engine kiểm giờ lái 2024 (số Yuki) + version rule | C16: F06 | E16: 18
A17: ENG-05 | B17: Import & đánh giá CSV nhiệt + alarm/deviation + completeness HACCP | C17: F07 | E17: 16
A18: ENG-06 | B18: Truy xuất 3 lane + recall đối soát số lượng | C18: F08 | E18: 14
A19: ENG-07 | B19: State machine 隔離 + bất biến/reversal + maker-checker nền | C19: F03 | E19: 12
A20: ENG-08 | B20: POD điều kiện (車上/軒先) + ảnh hash + offline queue | C20: F05 | E20: 10
A21: ENG-09 | B21: Interface: ERP SFTP, logger CSV, mapping, OIDC, mail, archive manifest | C21: F10 | E21: 22
A22: ENG-10 | B22: Audit append-only + 12 báo cáo + audit export manifest | C22: F09 | E22: 14
B23: Cộng engine | E23: =SUM(E13:E22) -> 148
A25: C. Các pha khác (design/NFR/migration/test/infra/training)
A26: Mã | B26: Pha / hoạt động | E26: MD
A27: P-RD | B27: Phân tích yêu cầu / BA (bám 88 FR/BR/NFR + compliance matrix) | E27: 26
A28: P-BD | B28: Thiết kế cơ bản (data model bất biến, state model, kiến trúc, 8 tuần) | E28: 30
A29: P-NFR | B29: NFR workstream: SSO/MFA/mã hóa, performance@80 + trace≤60s, BCP RTO4h/RPO15′, observability, WCAG 2.2 AA | E29: 40
A30: P-MIG | B30: Migration: lineage + 2 rehearsal + đối soát dirty data (2.5M nhiệt, 300k shipment) | E30: 30
A31: P-IT | B31: Integration test | E31: 18
A32: P-ST | B32: System test (gồm fixtures R-06 edge cases) | E32: 24
A33: P-UAT | B33: Hỗ trợ UAT (6 tuần) + 8 cổng nghiệm thu ACC-* | E33: 16
A34: P-INFRA | B34: Hạ tầng/DevOps/CI-CD + 4 môi trường (dev/test/UAT/prod) | E34: 16
A35: P-TRN | B35: Training theo role (JP) + 4 tuần hypercare | E35: 14
B36: Cộng pha khác | E36: =SUM(E27:E35) -> 214
A38: D. Tổng hợp effort
A39: Build (màn hình + engine) | E39: =E9+E23 -> 391.5
A40: Pha khác | E40: =E36 -> 214
A41: Cộng lõi (core) | E41: =E9+E23+E36 -> 605.5
A42: PM/PMO (15% core) | C42: 0.15 | E42: =E41*C42 -> 90.825
A43: Cộng (core + PM) | E43: =E41+E42 -> 696.325
A44: Dự phòng (10%) | C44: 0.1 | E44: =E43*C44 -> 69.6325
...

Sheet 08_Cost (S5-02)
A1: Deliverable — Cost sheet theo template S5-02
A2: Tách one-time / định kỳ / option. Mỗi dòng nêu giả định (user=80, dataset NFR-PERF-02). Đơn giá ¥/MD là giả định.
A4: Tổng effort (MD) từ sheet 07 | E4: ='07_Estimate-WBS'!$E$45 -> 765.9575
A5: Đơn giá bình quân ¥/MD (từ phân bổ role) | E5: 46660
A7: ① CHI PHÍ MỘT LẦN (one-time)
A8: Hạng mục | B8: Loại | C8: MD | D8: Đơn giá ¥/MD | E8: Chi phí ¥
A9: Thiết kế / build / test | B9: Một lần | C9: =E4-C10-C11 -> 710.2975 | D9: =E5 -> 46660 | E9: =C9*D9 -> 33142481
A10: Migration (2 rehearsal + final) | B10: Một lần | C10: ='07_Estimate-WBS'!$E$30*(E4/'07_Estimate-WBS'!$E$41) -> 37.95 | D10: =E5 -> 46660 | E10: =C10*D10 -> 1770747
A11: Training + 4 tuần hypercare | B11: Một lần | C11: ='07_Estimate-WBS'!$E$35*(E4/'07_Estimate-WBS'!$E$41) -> 17.71 | D11: =E5 -> 46660 | E11: =C11*D11 -> 826348.6
A12: Công tác phí onsite (nếu có) | B12: Một lần/định kỳ | C12: — | D12: — | E12: cần xác nhận Q-09
A13: Cộng one-time (¥) | E13: =SUM(E9:E11) -> 35739577
A14: Cộng one-time quy đổi (VND, 170₫/¥) | E14: =E13*170 -> 6.0757281e+09
A16: ② CHI PHÍ ĐỊNH KỲ (recurring) — nêu giả định tải; đơn giá cần xác nhận
A17: Hạng mục | B17: Loại | C17: Đơn vị | E17: Giả định
A18: Software license | B18: Định kỳ | C18: ¥/user·tháng hoặc /site | E18: Nêu rõ mô hình; phụ thuộc kiến trúc & bên thứ ba
A19: Cloud / hosting | B19: Định kỳ | C19: ¥/tháng | E19: Theo tải 80 concurrent + dataset NFR-PERF-02
A20: Support sau hypercare (SLA) | B20: Định kỳ | C20: ¥/tháng | E20: Kèm severity matrix & SLA
A22: ③ OPTION (S3-05 ngoài base) — KHÔNG cộng vào tổng cơ sở
A23: Hạng mục | B23: Loại | E23: Ghi chú
A24: Online datalogger / IoT platform | B24: Option | E24: S3-05 ngoài base
A25: Dự báo nhu cầu / tối ưu bổ sung / auto-waste | B25: Option | E25: S3-05 ngoài base
A26: Cổng truy xuất toàn quốc cho mọi SKU | B26: Option | E26: Hiện chỉ 3 lane gạo/bò/nội bộ
A27: GPS liên tục / SMS | B27: Option | E27: S3-05 ngoài base
A29: Giả định chi phí
A30: • Đơn giá ¥/MD là GIẢ ĐỊNH tham khảo (offshore VN) — sales & khách xác nhận (S5-02 cấm số làm tròn vô căn cứ).
A31: • Mỗi dòng nêu giả định: user=80 (NFR-PERF-01), dataset=300k shipment + 2,5M temp (NFR-PERF-02).
A32: • Option KHÔNG cộng vào tổng cơ sở (S3-05/S5-02).
A33: • Thuế tách khỏi đơn giá chưa thuế; tiền tệ & điều khoản thanh toán nêu trong proposal, chốt khi thương thảo (S5-04).
A34: • Tỉ giá tham khảo quy đổi: 1 JPY ≈ 170 VND (cập nhật khi báo giá).

Sheet 09_Rui ro
A1: Deliverable 7 — Rủi ro sơ bộ
A2: R-01..R-04 = 4 'lỗi nghiêm trọng' (重大エラー) RFP S5-03 cảnh báo trừ điểm.
A4: ID | B4: Rủi ro | C4: Nhóm | D4: K.năng | E4: T.động | F4: Mức | G4: Giảm thiểu | H4: Ảnh hưởng
A5: R-01 | B5: Nhầm 賞味/消費 khi thiết kế cảnh báo | C5: Đọc-hiểu (重大エラー) | D5: TB | E5: Cao | F5: Cao | G5: Cấu hình loại hạn theo SKU; 消費 hard stop, 賞味 cảnh báo; test 2 luồng (R-06). | H5: Rework logic + mất điểm S5-03
A6: R-02 | B6: So 日付逆転 với hôm nay thay vì lịch sử cặp khách-SKU | C6: Đọc-hiểu (重大エラー) | D6: Cao | E6: Cao | F6: Cao | G6: Dựa lịch sử bất biến DR-HIST-01; test CUS-003/CHI-002; chốt sớm. | H6: Sai lõi, mất điểm nặng
A7: R-03 | B7: Gọi quy tắc 1/3 là luật / chặn cứng | C7: Đọc-hiểu (重大エラー) | D7: TB | E7: Cao | F7: Cao | G7: 1/3-1/2 là 商慣習 (R-08 SRC-EXT-08); chỉ cảnh báo; tách khỏi 消費 hard stop. | H7: Mất điểm nặng
A8: R-04 | B8: Bỏ/nới ràng buộc cứng giờ lái | C8: Đọc-hiểu (重大エラー) | D8: TB | E8: Cao | F8: Cao | G8: Hard constraint trong ENG-04 theo số Yuki; cấm publish khi vi phạm. | H8: Mất điểm nặng + vi phạm luật
A9: R-05 | B9: Phủ thiếu 88 yêu cầu trong compliance matrix | C9: Phạm vi/đánh giá | D9: TB | E9: Cao | F9: Cao | G9: Ma trận Comply/Partial/Assumption đầy đủ; mỗi Partial/Assumption nêu scope/effort/cost. | H9: FR/BR chiếm 25% điểm
A10: R-06 | B10: Không đạt NFR (80 user, trace≤60s, WCAG, BCP) | C10: Phi chức năng | D10: TB | E10: Cao | F10: Cao | G10: NFR workstream riêng + load test 80 + dataset 300k/2,5M + restore drill + audit WCAG. | H10: NFR 15% điểm; rủi ro nghiệm thu ACC-NFR-01
A11: R-07 | B11: Migration dirty data (HSD trống, đổi mã khách, hoàn âm, 2,5M nhiệt) | C11: Dữ liệu | D11: Cao | E11: Cao | F11: Cao | G11: Lineage + 2 rehearsal + đối soát + business sign-off; không suy diễn ngày. | H11: Rủi ro cutover & 日付逆転
A12: R-08 | B12: Phụ thuộc bên ngoài: IdP/OIDC, mapping license, đặc tả ERP | C12: Phụ thuộc | D12: TB | E12: TB | F12: TB | G12: Chốt sớm (Assumption trong matrix + câu hỏi); thiết kế adapter. | H12: Trễ tiến độ nếu chậm cấp
A13: R-09 | B13: Kiến trúc event bất biến + maker-checker phức tạp hơn CRUD | C13: Kỹ thuật | D13: TB | E13: TB | F13: TB | G13: Chuẩn hóa nền event/version sớm (ENG-07); spike kỹ thuật giai đoạn BD. | H13: Tăng effort nếu làm muộn
A14: R-10 | B14: Critical path tới go-live 2027-06-01 | C14: Tiến độ | D14: TB | E14: Cao | F14: Cao | G14: Bám khung RFP (BD 8t/build-test 18t/UAT 6t); 2 rehearsal; kế hoạch rollback. | H14: Trễ go-live
A15: R-11 | B15: Dòng hợp đồng chưa chốt (AGR-008/014) bị suy diễn | C15: Đọc-hiểu | D15: Thấp | E15: TB | F15: Thấp | G15: Giữ business-review; không mặc định ONE_THIRD/ONE_HALF. | H15: Sai nghiệp vụ nhỏ
A16: R-12 | B16: Bò 9 số tự làm tròn thành 10 | C16: Đọc-hiểu | D16: Thấp | E16: Cao | F16: TB | G16: 9 số → business-review (R-06); không auto-round. | H16: Sai truy xuất pháp định

Sheet 10_Du lieu RFP
A1: Dữ liệu nền RFP — 12 SKU + sự thật nền
A2: Trích R-02/R-01/S1. Dùng làm tiền đề & dữ liệu demo (fixtures).
A4: SKU | B4: Tên (JP) | C4: Dải | D4: Loại hạn | E4: Lane | F4: Ghi chú
A5: AMB-001 | B5: 新潟県産包装精米5kg | C5: 常温 | D5: 賞味期限 | E5: rice | F5: Gạo — 産地+取引 (米トレーサビリティ法)
A6: AMB-002 | B6: 玄米せんべい12枚 | C6: 常温 | D6: 賞味期限 | E6: internal_lot | F6: —
A7: AMB-003 | B7: レトルト野菜カレー200g | C7: 常温 | D7: 賞味期限 | E7: internal_lot | F7: —
A8: AMB-004 | B8: ほうじ茶ティーバッグ20包 | C8: 常温 | D8: 賞味期限 | E8: internal_lot | F8: —
A9: CHI-001 | B9: 国産牛スライス200g | C9: 冷蔵 | D9: 消費期限 | E9: beef | F9: Bò — mã cá thể 10 số (牛トレーサビリティ法)
A10: CHI-002 | B10: プレーンヨーグルト400g | C10: 冷蔵 | D10: 賞味期限 | E10: internal_lot | F10: Dùng trong test 日付逆転 (CUS-003)
A11: CHI-003 | B11: 絹ごし豆腐300g | C11: 冷蔵 | D11: 消費期限 | E11: internal_lot | F11: —
A12: CHI-004 | B12: カットサラダ150g | C12: 冷蔵 | D12: 消費期限 | E12: internal_lot | F12: —
A13: FRO-001 | B13: 冷凍えび餃子12個 | C13: 冷凍 | D13: 賞味期限 | E13: internal_lot | F13: —
A14: FRO-002 | B14: バニラアイス120ml | C14: 冷凍 | D14: 賞味期限 | E14: internal_lot | F14: —
A15: FRO-003 | B15: 冷凍うどん5食 | C15: 冷凍 | D15: 賞味期限 | E15: internal_lot | F15: —
A16: FRO-004 | B16: 冷凍枝豆400g | C16: 冷凍 | D16: 賞味期限 | E16: internal_lot | F16: —
A18: Sự thật nền | B18: (đã sửa theo RFP)
A19: Quy mô | B19: 1 trung tâm (DC) duy nhất; 42 nhân sự: 18 kho, 9 tài xế, 4 配送計画, 3 QA, 3 sales/CS, 2 IT, 3 admin
A20: Cửa | B20: 2 cửa nhập, 3 cửa xuất; 1 khu 隔離 vật lý (chia theo dải nhiệt: C-Q, F-Q; 常温 không có -Q)
A21: 3 dải nhiệt (Yuki tự công bố) | B21: 常温 15–25°C · 冷蔵 0–5°C · 冷凍 ≤ −18°C (version theo ngày hiệu lực, BR-TEMP-01)
A22: Logger | B22: Ghi mỗi 15 phút theo zone (DL-A01/C01/F01); xuất CSV (không kết nối live — online là option)
A23: Số SKU | B23: 12 SKU (4/dải) — R-02; chỉ gạo (AMB-001) & bò (CHI-001) có truy xuất pháp định
A24: Khối lượng (3 tháng mẫu) | B24: Nhập ~1.800 dòng/tháng · Xuất ~7.200 dòng/tháng
A25: Hợp đồng khách-SKU | B25: 15 agreement (R-04); delivery window: ONE_THIRD / ONE_HALF / LABEL_DATE_ONLY; 2 dòng (AGR-008/014) CHƯA chốt — không mặc định
A26: Concurrent users | B26: 80 (NFR-PERF-01) — KHÔNG quy về 42; test tải đúng 80
A27: Service time | B27: 05:00–23:00 JST, 2 ca; AVL 99.5%/tháng (NFR-AVL-01)
A28: Dataset test hiệu năng | B28: 300.000 shipment lines + 2,5 triệu temperature readings (NFR-PERF-02, R-03)
A29: Timeline | B29: Start 2026-10-05 · Basic design 8 tuần · Build+Test 18 tuần · 2 migration rehearsal · UAT 6 tuần · Go-live 2027-06-01
